<?xml	version="1.0"?>
<robot	name="simba">
	<link	name="world"/>
	<link	name="base_link">
		<visual>
			<geometry>
				<cylinder	length="0.05"	radius="0.35"/>
			</geometry>
			<material name="aluminium">
				<color	rgba="0.75	0.75	0.75	1"/>
			</material>
				<origin	rpy="0 0 0"	xyz="0	0 0"/>
		</visual>
		<collision>
			<geometry>
				<cylinder	length="0.05"	radius="0.1"/>
			</geometry>
			<origin	rpy="0	0	0"	xyz="0	0	0.025"/>
		</collision>
		<inertial>
			<mass	value="0.520"/>
			<origin	rpy="0	0	0"	xyz="0	0	0.025"/>
			<inertia	ixx="1"	iyy="1"	izz="1"
							ixy="0"	ixz="0"	iyz="0"/>
		</inertial>
	</link>
	<joint	name="J0" type="fixed">
			<parent	link="world"/>
			<child	link="base_link"/>
	</joint>





	<link	name="l1">
		<visual>
			<geometry>
				<cylinder	length="0.15"	radius="0.15"/>
			</geometry>
			<material name="aluminium">
				<color	rgba="0.75	0.75	0.75	1"/>
			</material>
				<origin	rpy="0 0 0"	xyz="0	0 0"/>
		</visual>
		<collision>
			<geometry>
				<cylinder	length="0.15"	radius="0.15"/>
			</geometry>
			<origin	rpy="0	0	0"	xyz="0	0	0.025"/>
		</collision>
		<inertial>
			<mass	value="0.520"/>
			<origin	rpy="0	0	0"	xyz="0	0	0.025"/>
			<inertia	ixx="1"	iyy="1"	izz="1"
							ixy="0"	ixz="0"	iyz="0"/>
		</inertial>
	</link>
	<joint	name="J1" type="continuous">
			<axis xyz="0 0 1"/>
			<parent	link="base_link"/>
			<child	link="l1"/>
			<origin rpy="0 0 0" xyz="0.0 0.0 0.05"/>
	</joint>




	<link	name="joint_visual_1">
		<visual>
			<geometry>
				<cylinder length="0.1" radius = "0.05"/>
			</geometry>
			<material name="aluminium">
				<color	rgba="0.5 0.5 0.5 0.5"/>
			</material>
				<origin	rpy="0 1.61 0"	xyz="0	0 0"/>
		</visual>
		<collision>
			<geometry>
				<cylinder length="0.1" radius = "0.05"/>
			</geometry>
			<origin	rpy="0	0	0"	xyz="0	0	0.025"/>
		</collision>
		<inertial>
			<mass	value="0.520"/>
			<origin	rpy="0	0	0"	xyz="0	0	0.025"/>
			<inertia	ixx="1"	iyy="1"	izz="1"
							ixy="0"	ixz="0"	iyz="0"/>
		</inertial>

	</link>
	<joint	name="J2" type="continuous">
			<axis xyz="1 0 0"/>
			<parent	link="l1"/>
			<child	link="joint_visual_1"/>
			<origin rpy="0 0 0" xyz="0.0 0.0 0.13"/>
	</joint>




	<link	name="l2">
		<visual>
			<geometry>
				<box size="0.1 0.1 0.340"/>
			</geometry>
			<material name="aluminium">
				<color	rgba="1	1 1 1"/>
			</material>
				<origin	rpy="0 0 0"	xyz="0	0 0"/>
		</visual>
		<collision>
			<geometry>
				<box size="0.1 0.1 0.340"/>
			</geometry>
			<origin	rpy="0	0	0"	xyz="0	0	0.025"/>
		</collision>
		<inertial>
			<mass	value="0.520"/>
			<origin	rpy="0	0	0"	xyz="0	0	0.025"/>
			<inertia	ixx="1"	iyy="1"	izz="1"
							ixy="0"	ixz="0"	iyz="0"/>
		</inertial>

	</link>

	<joint	name="J3" type="fixed">
			<axis xyz="1 0 0"/>
			<parent	link="joint_visual_1"/>
			<child	link="l2"/>
			<origin rpy="0 0 0" xyz="0.0 0.0 0.21"/>
	</joint>



	<link	name="joint_visual_2">
		<visual>
			<geometry>
				<cylinder length="0.1" radius = "0.05"/>
			</geometry>
			<material name="aluminium">
				<color	rgba="0.5 0.5 0.5 0.5"/>
			</material>
				<origin	rpy="0 1.61 0"	xyz="0	0 0"/>
		</visual>
		<collision>
			<geometry>
				<cylinder length="0.1" radius = "0.05"/>
			</geometry>
			<origin	rpy="0	0	0"	xyz="0	0	0.025"/>
		</collision>
		<inertial>
			<mass	value="0.05"/>
			<origin	rpy="0	0	0"	xyz="0	0	0.025"/>
			<inertia	ixx="1"	iyy="1"	izz="1"
							ixy="0"	ixz="0"	iyz="1"/>
		</inertial>

	</link>
	<joint	name="J4" type="continuous">
			<axis xyz="1 0 0"/>
			<parent	link="l2"/>
			<child	link="joint_visual_2"/>
			<origin rpy="0 0 0" xyz="0.0 0.0 0.220"/>
	</joint>




	<link	name="l3">
		<visual>
			<geometry>
				<box size="0.1 0.1 0.340"/>
			</geometry>
			<material name="aluminium">
				<color	rgba="1	1 1 1"/>
			</material>
				<origin	rpy="0 0 0"	xyz="0	0 0"/>
		</visual>
		<collision>
			<geometry>
				<box size="0.1 0.1 0.340"/>
			</geometry>
			<origin	rpy="0	0	0"	xyz="0	0	0.025"/>
		</collision>
		<inertial>
			<mass	value="0.520"/>
			<origin	rpy="0	0	0"	xyz="0	0	0.025"/>
			<inertia	ixx="1"	iyy="1"	izz="1"
							ixy="0"	ixz="0"	iyz="0"/>
		</inertial>

	</link>
	<joint	name="J5" type="fixed">
			<axis xyz="1 0 0"/>
			<parent	link="joint_visual_2"/>
			<child	link="l3"/>
			<origin rpy="0 0 0" xyz="0.0 0.0 0.215"/>
	</joint>






	<link	name="gripper">
		<visual>
			<geometry>
				<box size="0.1 0.1 0.05"/>
			</geometry>
			<material name="aluminium">
				<color	rgba="1	1 1 1"/>
			</material>
				<origin	rpy="0 0 0"	xyz="0	0 0"/>
		</visual>
		<collision>
			<geometry>
				<box size="0.1 0.1 0.1"/>
			</geometry>
			<origin	rpy="0	0	0"	xyz="0	0 0"/>
		</collision>
		<inertial>
			<mass	value="0.200"/>
			<origin	rpy="0	0	0"	xyz="0	0	0.025"/>
			<inertia	ixx="1"	iyy="1"	izz="1"
							ixy="0"	ixz="0"	iyz="0"/>
		</inertial>

	</link>
	<joint	name="J6" type="fixed">
			<axis xyz="1 0 0"/>
			<parent	link="l3"/>
			<child	link="gripper"/>
			<origin rpy="0 0 0" xyz="0.0 0.0 0.2"/>
	</joint>



	<transmission name="tran0">
		<type>transmission_interface/SimpleTransmission</type>
		<joint name="J1">
			<hardwareInterface>PositionJointInterface</hardwareInterface>
		</joint>
		<actuator name="motor0">
			<hardwareInterface>PositionJointInterface</hardwareInterface>
			<mechanicalReduction>1</mechanicalReduction>
		</actuator>
	</transmission>


	<transmission name="tran1">
		<type>transmission_interface/SimpleTransmission</type>
		<joint name="J2">
			<hardwareInterface>PositionJointInterface</hardwareInterface>
		</joint>
		<actuator name="motor1">
			<hardwareInterface>PositionJointInterface</hardwareInterface>
			<mechanicalReduction>1</mechanicalReduction>
		</actuator>
	</transmission>



	<transmission name="tran2">
		<type>transmission_interface/SimpleTransmission</type>
		<joint name="J4">
			<hardwareInterface>PositionJointInterface</hardwareInterface>
		</joint>
		<actuator name="motor2">
			<hardwareInterface>PositionJointInterface</hardwareInterface>
			<mechanicalReduction>1</mechanicalReduction>
		</actuator>
	</transmission>
</robot>
